{"trial_id": "0000", "hyperparameters": {"space": [{"class_name": "Int", "config": {"name": "units_1", "default": null, "conditions": [], "min_value": 32, "max_value": 256, "step": 32, "sampling": "linear"}}, {"class_name": "Float", "config": {"name": "dropout_1", "default": 0.1, "conditions": [], "min_value": 0.1, "max_value": 0.5, "step": 0.1, "sampling": "linear"}}, {"class_name": "Int", "config": {"name": "units_2", "default": null, "conditions": [], "min_value": 32, "max_value": 128, "step": 32, "sampling": "linear"}}, {"class_name": "Float", "config": {"name": "dropout_2", "default": 0.1, "conditions": [], "min_value": 0.1, "max_value": 0.5, "step": 0.1, "sampling": "linear"}}, {"class_name": "Int", "config": {"name": "units_3", "default": null, "conditions": [], "min_value": 16, "max_value": 64, "step": 16, "sampling": "linear"}}, {"class_name": "Float", "config": {"name": "dropout_3", "default": 0.1, "conditions": [], "min_value": 0.1, "max_value": 0.5, "step": 0.1, "sampling": "linear"}}, {"class_name": "Int", "config": {"name": "dense_units", "default": null, "conditions": [], "min_value": 8, "max_value": 64, "step": 8, "sampling": "linear"}}, {"class_name": "Choice", "config": {"name": "learning_rate", "default": 0.001, "conditions": [], "values": [0.001, 0.005, 0.01, 0.05], "ordered": true}}], "values": {"units_1": 96, "dropout_1": 0.30000000000000004, "units_2": 64, "dropout_2": 0.4, "units_3": 16, "dropout_3": 0.4, "dense_units": 48, "learning_rate": 0.005, "tuner/epochs": 2, "tuner/initial_epoch": 0, "tuner/bracket": 3, "tuner/round": 0}}, "metrics": {"metrics": {}}, "score": null, "best_step": 0, "status": "FAILED", "message": "Traceback (most recent call last):\n  File \"c:\\Users\\saidi\\AppData\\Local\\Programs\\Python\\Python311\\Lib\\site-packages\\keras_tuner\\src\\engine\\base_tuner.py\", line 274, in _try_run_and_update_trial\n    self._run_and_update_trial(trial, *fit_args, **fit_kwargs)\n  File \"c:\\Users\\saidi\\AppData\\Local\\Programs\\Python\\Python311\\Lib\\site-packages\\keras_tuner\\src\\engine\\base_tuner.py\", line 239, in _run_and_update_trial\n    results = self.run_trial(trial, *fit_args, **fit_kwargs)\n              ^^^^^^^^^^^^^^^^^^^^^^^^^^^^^^^^^^^^^^^^^^^^^^\n  File \"c:\\Users\\saidi\\AppData\\Local\\Programs\\Python\\Python311\\Lib\\site-packages\\keras_tuner\\src\\tuners\\hyperband.py\", line 427, in run_trial\n    return super().run_trial(trial, *fit_args, **fit_kwargs)\n           ^^^^^^^^^^^^^^^^^^^^^^^^^^^^^^^^^^^^^^^^^^^^^^^^^\n  File \"c:\\Users\\saidi\\AppData\\Local\\Programs\\Python\\Python311\\Lib\\site-packages\\keras_tuner\\src\\engine\\tuner.py\", line 314, in run_trial\n    obj_value = self._build_and_fit_model(trial, *args, **copied_kwargs)\n                ^^^^^^^^^^^^^^^^^^^^^^^^^^^^^^^^^^^^^^^^^^^^^^^^^^^^^^^^\n  File \"c:\\Users\\saidi\\AppData\\Local\\Programs\\Python\\Python311\\Lib\\site-packages\\keras_tuner\\src\\engine\\tuner.py\", line 233, in _build_and_fit_model\n    results = self.hypermodel.fit(hp, model, *args, **kwargs)\n              ^^^^^^^^^^^^^^^^^^^^^^^^^^^^^^^^^^^^^^^^^^^^^^^\n  File \"c:\\Users\\saidi\\AppData\\Local\\Programs\\Python\\Python311\\Lib\\site-packages\\keras_tuner\\src\\engine\\hypermodel.py\", line 149, in fit\n    return model.fit(*args, **kwargs)\n           ^^^^^^^^^^^^^^^^^^^^^^^^^^\n  File \"c:\\Users\\saidi\\AppData\\Local\\Programs\\Python\\Python311\\Lib\\site-packages\\keras\\src\\utils\\traceback_utils.py\", line 70, in error_handler\n  File \"C:\\Users\\saidi\\AppData\\Local\\Temp\\__autograph_generated_filelrsv5yqb.py\", line 18, in tf__train_function\n    raise\nValueError: in user code:\n\n    File \"c:\\Users\\saidi\\AppData\\Local\\Programs\\Python\\Python311\\Lib\\site-packages\\keras\\src\\engine\\training.py\", line 1401, in train_function  *\n        return step_function(self, iterator)\n    File \"c:\\Users\\saidi\\AppData\\Local\\Programs\\Python\\Python311\\Lib\\site-packages\\keras\\src\\engine\\training.py\", line 1384, in step_function  **\n        \n    File \"c:\\Users\\saidi\\AppData\\Local\\Programs\\Python\\Python311\\Lib\\site-packages\\keras\\src\\engine\\training.py\", line 1373, in run_step  **\n        \n    File \"c:\\Users\\saidi\\AppData\\Local\\Programs\\Python\\Python311\\Lib\\site-packages\\keras\\src\\engine\\training.py\", line 1151, in train_step\n        \n    File \"c:\\Users\\saidi\\AppData\\Local\\Programs\\Python\\Python311\\Lib\\site-packages\\keras\\src\\engine\\training.py\", line 1209, in compute_loss\n        \n    File \"c:\\Users\\saidi\\AppData\\Local\\Programs\\Python\\Python311\\Lib\\site-packages\\keras\\src\\engine\\compile_utils.py\", line 277, in __call__\n        \n    File \"c:\\Users\\saidi\\AppData\\Local\\Programs\\Python\\Python311\\Lib\\site-packages\\keras\\src\\losses.py\", line 143, in __call__\n        \n    File \"c:\\Users\\saidi\\AppData\\Local\\Programs\\Python\\Python311\\Lib\\site-packages\\keras\\src\\losses.py\", line 270, in call  **\n        \n    File \"c:\\Users\\saidi\\AppData\\Local\\Programs\\Python\\Python311\\Lib\\site-packages\\keras\\src\\losses.py\", line 2221, in categorical_crossentropy\n        \n    File \"c:\\Users\\saidi\\AppData\\Local\\Programs\\Python\\Python311\\Lib\\site-packages\\keras\\src\\backend.py\", line 5573, in categorical_crossentropy\n        \n\n    ValueError: Shapes (32, 1) and (32, 5) are incompatible\n\n"}